<?xml version="1.0" ?>
<robot name="glove_hand">
  <!-- World frame -->
  <link name="world"/>
  
  <!-- ======================== THUMB ======================== -->
  <link name="thumb_origin">
    <inertial>
      <mass value="0.1"/>
      <inertia ixx="0.001" ixy="0.0" ixz="0.0" iyy="0.001" iyz="0.0" izz="0.001"/>
    </inertial>
    <visual>
      <geometry>
        <sphere radius="0.005"/>
      </geometry>
      <material name="red">
        <color rgba="1.0 0.0 0.0 1.0"/>
      </material>
    </visual>
    <collision>
      <geometry>
        <sphere radius="0.005"/>
      </geometry>
    </collision>
  </link>

  <joint name="thumb_origin_joint" type="fixed">
    <parent link="world"/>
    <child link="thumb_origin"/>
    <origin xyz="0 -10 5" rpy="0 0 0"/>
  </joint>

  <!-- Thumb Link 1 (l1: 40mm) -->
  <link name="thumb_l1">
    <inertial>
      <mass value="0.05"/>
      <inertia ixx="0.00005" ixy="0.0" ixz="0.0" iyy="0.00005" iyz="0.0" izz="0.00005"/>
    </inertial>
    <visual>
      <geometry>
        <cylinder radius="0.003" length="0.040"/>
      </geometry>
      <origin xyz="0.020 0 0" rpy="0 1.5708 0"/>
      <material name="blue">
        <color rgba="0.0 0.0 1.0 1.0"/>
      </material>
    </visual>
    <collision>
      <geometry>
        <cylinder radius="0.003" length="0.040"/>
      </geometry>
      <origin xyz="0.020 0 0" rpy="0 1.5708 0"/>
    </collision>
  </link>

  <joint name="thumb_l1_joint" type="revolute">
    <parent link="thumb_origin"/>
    <child link="thumb_l1"/>
    <origin xyz="0 0 0" rpy="0 0 0"/>
    <axis xyz="0 0 1"/>
    <limit lower="-1.5708" upper="1.5708" effort="10" velocity="1.0"/>
  </joint>

  <!-- Thumb Link 2 (l2: 40mm) -->
  <link name="thumb_l2">
    <inertial>
      <mass value="0.05"/>
      <inertia ixx="0.00005" ixy="0.0" ixz="0.0" iyy="0.00005" iyz="0.0" izz="0.00005"/>
    </inertial>
    <visual>
      <geometry>
        <cylinder radius="0.003" length="0.040"/>
      </geometry>
      <origin xyz="0.020 0 0" rpy="0 1.5708 0"/>
      <material name="blue">
        <color rgba="0.0 0.0 1.0 1.0"/>
      </material>
    </visual>
    <collision>
      <geometry>
        <cylinder radius="0.003" length="0.040"/>
      </geometry>
      <origin xyz="0.020 0 0" rpy="0 1.5708 0"/>
    </collision>
  </link>

  <joint name="thumb_l2_joint" type="revolute">
    <parent link="thumb_l1"/>
    <child link="thumb_l2"/>
    <origin xyz="0.040 0 0" rpy="0 0 0"/>
    <axis xyz="0 0 1"/>
    <limit lower="-1.5708" upper="1.5708" effort="10" velocity="1.0"/>
  </joint>

  <!-- Thumb Link 3 (l3: 15mm) -->
  <link name="thumb_l3">
    <inertial>
      <mass value="0.03"/>
      <inertia ixx="0.00002" ixy="0.0" ixz="0.0" iyy="0.00002" iyz="0.0" izz="0.00002"/>
    </inertial>
    <visual>
      <geometry>
        <cylinder radius="0.002" length="0.015"/>
      </geometry>
      <origin xyz="0.0075 0 0" rpy="0 1.5708 0"/>
      <material name="green">
        <color rgba="0.0 1.0 0.0 1.0"/>
      </material>
    </visual>
    <collision>
      <geometry>
        <cylinder radius="0.002" length="0.015"/>
      </geometry>
      <origin xyz="0.0075 0 0" rpy="0 1.5708 0"/>
    </collision>
  </link>

  <joint name="thumb_l3_joint" type="revolute">
    <parent link="thumb_l2"/>
    <child link="thumb_l3"/>
    <origin xyz="0.040 0 0" rpy="0 0 0"/>
    <axis xyz="0 0 1"/>
    <limit lower="-1.5708" upper="1.5708" effort="10" velocity="1.0"/>
  </joint>

  <!-- Thumb Link 4 (l4: 45mm) -->
  <link name="thumb_l4">
    <inertial>
      <mass value="0.05"/>
      <inertia ixx="0.00005" ixy="0.0" ixz="0.0" iyy="0.00005" iyz="0.0" izz="0.00005"/>
    </inertial>
    <visual>
      <geometry>
        <cylinder radius="0.003" length="0.045"/>
      </geometry>
      <origin xyz="0.0225 0 0" rpy="0 1.5708 0"/>
      <material name="blue">
        <color rgba="0.0 0.0 1.0 1.0"/>
      </material>
    </visual>
    <collision>
      <geometry>
        <cylinder radius="0.003" length="0.045"/>
      </geometry>
      <origin xyz="0.0225 0 0" rpy="0 1.5708 0"/>
    </collision>
  </link>

  <joint name="thumb_l4_joint" type="revolute">
    <parent link="thumb_l3"/>
    <child link="thumb_l4"/>
    <origin xyz="0.015 0 0" rpy="0 0 0"/>
    <axis xyz="0 0 1"/>
    <limit lower="-1.5708" upper="1.5708" effort="10" velocity="1.0"/>
  </joint>

  <!-- Thumb Link 5 (l5: 55mm) -->
  <link name="thumb_l5">
    <inertial>
      <mass value="0.06"/>
      <inertia ixx="0.00006" ixy="0.0" ixz="0.0" iyy="0.00006" iyz="0.0" izz="0.00006"/>
    </inertial>
    <visual>
      <geometry>
        <cylinder radius="0.003" length="0.055"/>
      </geometry>
      <origin xyz="0.0275 0 0" rpy="0 1.5708 0"/>
      <material name="blue">
        <color rgba="0.0 0.0 1.0 1.0"/>
      </material>
    </visual>
    <collision>
      <geometry>
        <cylinder radius="0.003" length="0.055"/>
      </geometry>
      <origin xyz="0.0275 0 0" rpy="0 1.5708 0"/>
    </collision>
  </link>

  <joint name="thumb_l5_joint" type="revolute">
    <parent link="thumb_l4"/>
    <child link="thumb_l5"/>
    <origin xyz="0.045 0 0" rpy="0 0 0"/>
    <axis xyz="0 1 0"/>
    <limit lower="-1.5708" upper="1.5708" effort="10" velocity="1.0"/>
  </joint>

  <!-- Thumb Link 6 (l6: 55mm) -->
  <link name="thumb_l6">
    <inertial>
      <mass value="0.06"/>
      <inertia ixx="0.00006" ixy="0.0" ixz="0.0" iyy="0.00006" iyz="0.0" izz="0.00006"/>
    </inertial>
    <visual>
      <geometry>
        <cylinder radius="0.003" length="0.055"/>
      </geometry>
      <origin xyz="0.0275 0 0" rpy="0 1.5708 0"/>
      <material name="blue">
        <color rgba="0.0 0.0 1.0 1.0"/>
      </material>
    </visual>
    <collision>
      <geometry>
        <cylinder radius="0.003" length="0.055"/>
      </geometry>
      <origin xyz="0.0275 0 0" rpy="0 1.5708 0"/>
    </collision>
  </link>

  <joint name="thumb_l6_joint" type="revolute">
    <parent link="thumb_l5"/>
    <child link="thumb_l6"/>
    <origin xyz="0.055 0 0" rpy="0 0 0"/>
    <axis xyz="0 1 0"/>
    <limit lower="-1.5708" upper="1.5708" effort="10" velocity="1.0"/>
  </joint>

  <!-- Thumb Link 7 (l7: 40mm) -->
  <link name="thumb_l7">
    <inertial>
      <mass value="0.04"/>
      <inertia ixx="0.00004" ixy="0.0" ixz="0.0" iyy="0.00004" iyz="0.0" izz="0.00004"/>
    </inertial>
    <visual>
      <geometry>
        <cylinder radius="0.003" length="0.040"/>
      </geometry>
      <origin xyz="0.020 0 0" rpy="0 1.5708 0"/>
      <material name="blue">
        <color rgba="0.0 0.0 1.0 1.0"/>
      </material>
    </visual>
    <collision>
      <geometry>
        <cylinder radius="0.003" length="0.040"/>
      </geometry>
      <origin xyz="0.020 0 0" rpy="0 1.5708 0"/>
    </collision>
  </link>

  <joint name="thumb_l7_joint" type="revolute">
    <parent link="thumb_l6"/>
    <child link="thumb_l7"/>
    <origin xyz="0.055 0 0" rpy="0 0 0"/>
    <axis xyz="1 0 0"/>
    <limit lower="-1.5708" upper="1.5708" effort="10" velocity="1.0"/>
  </joint>

  <!-- ======================== FINGER 1 ======================== -->
  <link name="finger1_origin">
    <inertial>
      <mass value="0.1"/>
      <inertia ixx="0.001" ixy="0.0" ixz="0.0" iyy="0.001" iyz="0.0" izz="0.001"/>
    </inertial>
    <visual>
      <geometry>
        <sphere radius="0.005"/>
      </geometry>
      <material name="orange">
        <color rgba="1.0 0.5 0.0 1.0"/>
      </material>
    </visual>
    <collision>
      <geometry>
        <sphere radius="0.005"/>
      </geometry>
    </collision>
  </link>

  <joint name="finger1_origin_joint" type="fixed">
    <parent link="world"/>
    <child link="finger1_origin"/>
    <origin xyz="0 0 15" rpy="0 0 0"/>
  </joint>

  <!-- Finger 1 Link 1 (l1: 75mm) -->
  <link name="finger1_l1">
    <inertial>
      <mass value="0.08"/>
      <inertia ixx="0.00008" ixy="0.0" ixz="0.0" iyy="0.00008" iyz="0.0" izz="0.00008"/>
    </inertial>
    <visual>
      <geometry>
        <cylinder radius="0.003" length="0.075"/>
      </geometry>
      <origin xyz="0.0375 0 0" rpy="0 1.5708 0"/>
      <material name="cyan">
        <color rgba="0.0 1.0 1.0 1.0"/>
      </material>
    </visual>
    <collision>
      <geometry>
        <cylinder radius="0.003" length="0.075"/>
      </geometry>
      <origin xyz="0.0375 0 0" rpy="0 1.5708 0"/>
    </collision>
  </link>

  <joint name="finger1_l1_joint" type="revolute">
    <parent link="finger1_origin"/>
    <child link="finger1_l1"/>
    <origin xyz="0 0 0" rpy="0 0 0"/>
    <axis xyz="0 0 1"/>
    <limit lower="-1.5708" upper="1.5708" effort="10" velocity="1.0"/>
  </joint>

  <!-- Finger 1 Link 2 (l2: 95mm) -->
  <link name="finger1_l2">
    <inertial>
      <mass value="0.09"/>
      <inertia ixx="0.00009" ixy="0.0" ixz="0.0" iyy="0.00009" iyz="0.0" izz="0.00009"/>
    </inertial>
    <visual>
      <geometry>
        <cylinder radius="0.003" length="0.095"/>
      </geometry>
      <origin xyz="0.0475 0 0" rpy="0 1.5708 0"/>
      <material name="cyan">
        <color rgba="0.0 1.0 1.0 1.0"/>
      </material>
    </visual>
    <collision>
      <geometry>
        <cylinder radius="0.003" length="0.095"/>
      </geometry>
      <origin xyz="0.0475 0 0" rpy="0 1.5708 0"/>
    </collision>
  </link>

  <joint name="finger1_l2_joint" type="revolute">
    <parent link="finger1_l1"/>
    <child link="finger1_l2"/>
    <origin xyz="0.075 0 0" rpy="0 0 0"/>
    <axis xyz="0 1 0"/>
    <limit lower="-1.5708" upper="1.5708" effort="10" velocity="1.0"/>
  </joint>

  <!-- Finger 1 Link 3 (l3: 75mm) -->
  <link name="finger1_l3">
    <inertial>
      <mass value="0.08"/>
      <inertia ixx="0.00008" ixy="0.0" ixz="0.0" iyy="0.00008" iyz="0.0" izz="0.00008"/>
    </inertial>
    <visual>
      <geometry>
        <cylinder radius="0.003" length="0.075"/>
      </geometry>
      <origin xyz="0.0375 0 0" rpy="0 1.5708 0"/>
      <material name="cyan">
        <color rgba="0.0 1.0 1.0 1.0"/>
      </material>
    </visual>
    <collision>
      <geometry>
        <cylinder radius="0.003" length="0.075"/>
      </geometry>
      <origin xyz="0.0375 0 0" rpy="0 1.5708 0"/>
    </collision>
  </link>

  <joint name="finger1_l3_joint" type="revolute">
    <parent link="finger1_l2"/>
    <child link="finger1_l3"/>
    <origin xyz="0.095 0 0" rpy="0 0 0"/>
    <axis xyz="0 1 0"/>
    <limit lower="-1.5708" upper="1.5708" effort="10" velocity="1.0"/>
  </joint>

  <!-- Finger 1 Link 4 (l4: 40mm) -->
  <link name="finger1_l4">
    <inertial>
      <mass value="0.04"/>
      <inertia ixx="0.00004" ixy="0.0" ixz="0.0" iyy="0.00004" iyz="0.0" izz="0.00004"/>
    </inertial>
    <visual>
      <geometry>
        <cylinder radius="0.002" length="0.040"/>
      </geometry>
      <origin xyz="0.020 0 0" rpy="0 1.5708 0"/>
      <material name="magenta">
        <color rgba="1.0 0.0 1.0 1.0"/>
      </material>
    </visual>
    <collision>
      <geometry>
        <cylinder radius="0.002" length="0.040"/>
      </geometry>
      <origin xyz="0.020 0 0" rpy="0 1.5708 0"/>
    </collision>
  </link>

  <joint name="finger1_l4_joint" type="revolute">
    <parent link="finger1_l3"/>
    <child link="finger1_l4"/>
    <origin xyz="0.075 0 0" rpy="0 0 0"/>
    <axis xyz="0 1 0"/>
    <limit lower="-1.5708" upper="1.5708" effort="10" velocity="1.0"/>
  </joint>

  <!-- ======================== FINGER 2 ======================== -->
  <link name="finger2_origin">
    <inertial>
      <mass value="0.1"/>
      <inertia ixx="0.001" ixy="0.0" ixz="0.0" iyy="0.001" iyz="0.0" izz="0.001"/>
    </inertial>
    <visual>
      <geometry>
        <sphere radius="0.005"/>
      </geometry>
      <material name="yellow">
        <color rgba="1.0 1.0 0.0 1.0"/>
      </material>
    </visual>
    <collision>
      <geometry>
        <sphere radius="0.005"/>
      </geometry>
    </collision>
  </link>

  <joint name="finger2_origin_joint" type="fixed">
    <parent link="world"/>
    <child link="finger2_origin"/>
    <origin xyz="20 0 15" rpy="0 0 0"/>
  </joint>

  <!-- Finger 2 Link 1 (l1: 75mm) -->
  <link name="finger2_l1">
    <inertial>
      <mass value="0.08"/>
      <inertia ixx="0.00008" ixy="0.0" ixz="0.0" iyy="0.00008" iyz="0.0" izz="0.00008"/>
    </inertial>
    <visual>
      <geometry>
        <cylinder radius="0.003" length="0.075"/>
      </geometry>
      <origin xyz="0.0375 0 0" rpy="0 1.5708 0"/>
      <material name="purple">
        <color rgba="0.627 0.0 0.627 1.0"/>
      </material>
    </visual>
    <collision>
      <geometry>
        <cylinder radius="0.003" length="0.075"/>
      </geometry>
      <origin xyz="0.0375 0 0" rpy="0 1.5708 0"/>
    </collision>
  </link>

  <joint name="finger2_l1_joint" type="revolute">
    <parent link="finger2_origin"/>
    <child link="finger2_l1"/>
    <origin xyz="0 0 0" rpy="0 0 0"/>
    <axis xyz="0 0 1"/>
    <limit lower="-1.5708" upper="1.5708" effort="10" velocity="1.0"/>
  </joint>

  <!-- Finger 2 Link 2 (l2: 95mm) -->
  <link name="finger2_l2">
    <inertial>
      <mass value="0.09"/>
      <inertia ixx="0.00009" ixy="0.0" ixz="0.0" iyy="0.00009" iyz="0.0" izz="0.00009"/>
    </inertial>
    <visual>
      <geometry>
        <cylinder radius="0.003" length="0.095"/>
      </geometry>
      <origin xyz="0.0475 0 0" rpy="0 1.5708 0"/>
      <material name="purple">
        <color rgba="0.627 0.0 0.627 1.0"/>
      </material>
    </visual>
    <collision>
      <geometry>
        <cylinder radius="0.003" length="0.095"/>
      </geometry>
      <origin xyz="0.0475 0 0" rpy="0 1.5708 0"/>
    </collision>
  </link>

  <joint name="finger2_l2_joint" type="revolute">
    <parent link="finger2_l1"/>
    <child link="finger2_l2"/>
    <origin xyz="0.075 0 0" rpy="0 0 0"/>
    <axis xyz="0 1 0"/>
    <limit lower="-1.5708" upper="1.5708" effort="10" velocity="1.0"/>
  </joint>

  <!-- Finger 2 Link 3 (l3: 75mm) -->
  <link name="finger2_l3">
    <inertial>
      <mass value="0.08"/>
      <inertia ixx="0.00008" ixy="0.0" ixz="0.0" iyy="0.00008" iyz="0.0" izz="0.00008"/>
    </inertial>
    <visual>
      <geometry>
        <cylinder radius="0.003" length="0.075"/>
      </geometry>
      <origin xyz="0.0375 0 0" rpy="0 1.5708 0"/>
      <material name="purple">
        <color rgba="0.627 0.0 0.627 1.0"/>
      </material>
    </visual>
    <collision>
      <geometry>
        <cylinder radius="0.003" length="0.075"/>
      </geometry>
      <origin xyz="0.0375 0 0" rpy="0 1.5708 0"/>
    </collision>
  </link>

  <joint name="finger2_l3_joint" type="revolute">
    <parent link="finger2_l2"/>
    <child link="finger2_l3"/>
    <origin xyz="0.095 0 0" rpy="0 0 0"/>
    <axis xyz="0 1 0"/>
    <limit lower="-1.5708" upper="1.5708" effort="10" velocity="1.0"/>
  </joint>

  <!-- Finger 2 Link 4 (l4: 40mm) -->
  <link name="finger2_l4">
    <inertial>
      <mass value="0.04"/>
      <inertia ixx="0.00004" ixy="0.0" ixz="0.0" iyy="0.00004" iyz="0.0" izz="0.00004"/>
    </inertial>
    <visual>
      <geometry>
        <cylinder radius="0.002" length="0.040"/>
      </geometry>
      <origin xyz="0.020 0 0" rpy="0 1.5708 0"/>
      <material name="lime">
        <color rgba="0.0 1.0 0.0 1.0"/>
      </material>
    </visual>
    <collision>
      <geometry>
        <cylinder radius="0.002" length="0.040"/>
      </geometry>
      <origin xyz="0.020 0 0" rpy="0 1.5708 0"/>
    </collision>
  </link>

  <joint name="finger2_l4_joint" type="revolute">
    <parent link="finger2_l3"/>
    <child link="finger2_l4"/>
    <origin xyz="0.075 0 0" rpy="0 0 0"/>
    <axis xyz="0 1 0"/>
    <limit lower="-1.5708" upper="1.5708" effort="10" velocity="1.0"/>
  </joint>

  <!-- ======================== MATERIALS ======================== -->
  <material name="red">
    <color rgba="1.0 0.0 0.0 1.0"/>
  </material>
  <material name="blue">
    <color rgba="0.0 0.0 1.0 1.0"/>
  </material>
  <material name="green">
    <color rgba="0.0 1.0 0.0 1.0"/>
  </material>
  <material name="orange">
    <color rgba="1.0 0.5 0.0 1.0"/>
  </material>
  <material name="cyan">
    <color rgba="0.0 1.0 1.0 1.0"/>
  </material>
  <material name="yellow">
    <color rgba="1.0 1.0 0.0 1.0"/>
  </material>
  <material name="purple">
    <color rgba="0.627 0.0 0.627 1.0"/>
  </material>
  <material name="magenta">
    <color rgba="1.0 0.0 1.0 1.0"/>
  </material>
  <material name="lime">
    <color rgba="0.0 1.0 0.0 1.0"/>
  </material>

</robot>
