<?xml version="1.0"?>
<!--
  Robot: feedback_glove
  Generated by: LinkForge v1.2.0
  https://github.com/arounamounchili/linkforge
  Date: 2026-02-02 18:53:59
-->
<robot name="feedback_glove">
  <!-- Materials -->
  <material name="Material_004">
    <color rgba="0.800016 0.647821 0.007821 1" />
  </material>
  <material name="Material_003">
    <color rgba="0.180552 0.180552 0.180552 1" />
  </material>
  <material name="Material_001">
    <color rgba="0 0 0 1" />
  </material>
  <!-- Links -->
  <link name="base">
    <visual>
      <geometry>
        <mesh filename="package://glove_description/meshes/base_visual.stl" />
      </geometry>
      <material name="Material_004" />
    </visual>
    <collision>
      <origin xyz="20.366289 81.827148 -13.441046" rpy="0 0 0" />
      <geometry>
        <box size="118.08609 200 41.493954" />
      </geometry>
    </collision>
    <inertial>
      <mass value="1" />
      <inertia ixx="3476.81235" ixy="0" ixz="0" iyy="1305.506072" iyz="0" izz="4495.360389" />
    </inertial>
  </link>
  <link name="tl0">
    <visual>
      <geometry>
        <mesh filename="package://glove_description/meshes/tl0_visual.stl" />
      </geometry>
      <material name="Material_003" />
    </visual>
    <collision>
      <origin xyz="0.23243 -17.365746 4.371803" rpy="0 0 0" />
      <geometry>
        <box size="24.825493 42.810646 38.781082" />
      </geometry>
    </collision>
    <inertial>
      <mass value="1" />
      <inertia ixx="278.060312" ixy="0" ixz="0" iyy="176.689786" iyz="0" izz="204.088043" />
    </inertial>
  </link>
  <link name="Txc330">
    <visual>
      <geometry>
        <mesh filename="package://glove_description/meshes/Txc330_visual.stl" />
      </geometry>
      <material name="Material_001" />
    </visual>
    <collision>
      <origin xyz="0.046047 7.499992 6.499842" rpy="0 0 0" />
      <geometry>
        <box size="20.183695 34.000015 26.141058" />
      </geometry>
    </collision>
    <inertial>
      <mass value="1" />
      <inertia ixx="153.279662" ixy="0" ixz="0" iyy="90.894704" iyz="0" izz="130.281881" />
    </inertial>
  </link>
  <link name="tl1">
    <visual>
      <geometry>
        <mesh filename="package://glove_description/meshes/tl1_001_visual.stl" />
      </geometry>
      <material name="Material_003" />
    </visual>
    <collision>
      <origin xyz="-0.217117 -48.837063 -1.631042" rpy="0 0 0" />
      <geometry>
        <box size="18.212158 115.992867 12.568717" />
      </geometry>
    </collision>
    <inertial>
      <mass value="1" />
      <inertia ixx="1134.359811" ixy="0" ixz="0" iyy="40.804613" iyz="0" izz="1148.835649" />
    </inertial>
  </link>
  <link name="tl2">
    <visual>
      <geometry>
        <mesh filename="package://glove_description/meshes/tl2_001_visual.stl" />
      </geometry>
      <material name="Material_003" />
    </visual>
    <collision>
      <origin xyz="-0.005779 -29.956448 1.249594" rpy="0 0 0" />
      <geometry>
        <box size="14.144591 74.010262 12.10587" />
      </geometry>
    </collision>
    <inertial>
      <mass value="1" />
      <inertia ixx="468.672576" ixy="0" ixz="0" iyy="28.88513" iyz="0" izz="473.132356" />
    </inertial>
  </link>
  <link name="tl3">
    <visual>
      <geometry>
        <mesh filename="package://glove_description/meshes/tl3_visual.stl" />
      </geometry>
      <material name="Material_003" />
    </visual>
    <collision>
      <origin xyz="11.426994 -14.165771 0.006521" rpy="0 0 0" />
      <geometry>
        <box size="36.27364 39.274078 28.458366" />
      </geometry>
    </collision>
    <inertial>
      <mass value="1" />
      <inertia ixx="196.027654" ixy="0" ixz="0" iyy="177.137963" iyz="0" izz="238.185847" />
    </inertial>
  </link>
  <link name="bridge">
    <visual>
      <geometry>
        <mesh filename="package://glove_description/meshes/bridge_visual.stl" />
      </geometry>
      <material name="Material_004" />
    </visual>
    <collision>
      <origin xyz="0.392461 -0.753861 23.125851" rpy="0 0 0" />
      <geometry>
        <box size="72.021408 20 38.5" />
      </geometry>
    </collision>
    <inertial>
      <mass value="1" />
      <inertia ixx="156.854167" ixy="0" ixz="0" iyy="555.777768" iyz="0" izz="465.590268" />
    </inertial>
  </link>
  <link name="f1l0">
    <visual>
      <geometry>
        <mesh filename="package://glove_description/meshes/f1l0_visual.stl" />
      </geometry>
      <material name="Material_003" />
    </visual>
    <collision>
      <origin xyz="4.37344 -17.365738 -0.199278" rpy="0 0 0" />
      <geometry>
        <box size="38.596191 42.810646 24.533583" />
      </geometry>
    </collision>
    <inertial>
      <mass value="1" />
      <inertia ixx="202.887341" ixy="0" ixz="0" iyy="174.296889" iyz="0" izz="276.868117" />
    </inertial>
  </link>
  <link name="f1xc330">
    <visual>
      <geometry>
        <mesh filename="package://glove_description/meshes/f1xc330_visual.stl" />
      </geometry>
      <material name="Material_001" />
    </visual>
    <collision>
      <origin xyz="6.500004 7.499996 0.000002" rpy="0 0 0" />
      <geometry>
        <box size="26.000019 34.000011 20.000008" />
      </geometry>
    </collision>
    <inertial>
      <mass value="1" />
      <inertia ixx="129.666757" ixy="0" ixz="0" iyy="89.666775" iyz="0" izz="152.666814" />
    </inertial>
  </link>
  <link name="f1l1">
    <visual>
      <geometry>
        <mesh filename="package://glove_description/meshes/f1l1_visual.stl" />
      </geometry>
      <material name="Material_003" />
    </visual>
    <collision>
      <origin xyz="-1.632231 -48.834408 0.550089" rpy="0 0 0" />
      <geometry>
        <box size="12.441303 116.116333 18.942066" />
      </geometry>
    </collision>
    <inertial>
      <mass value="1" />
      <inertia ixx="1153.483722" ixy="0" ixz="0" iyy="42.798992" iyz="0" izz="1136.482401" />
    </inertial>
  </link>
  <link name="f1l2">
    <visual>
      <geometry>
        <mesh filename="package://glove_description/meshes/f1l2_visual.stl" />
      </geometry>
      <material name="Material_003" />
    </visual>
    <collision>
      <origin xyz="1.249349 -29.956177 -0.131289" rpy="0 0 0" />
      <geometry>
        <box size="12.000027 74.07753 14.415758" />
      </geometry>
    </collision>
    <inertial>
      <mass value="1" />
      <inertia ixx="474.607877" ixy="0" ixz="0" iyy="29.317894" iyz="0" izz="469.29009" />
    </inertial>
  </link>
  <link name="f1l3">
    <visual>
      <geometry>
        <mesh filename="package://glove_description/meshes/f1l3_visual.stl" />
      </geometry>
      <material name="Material_003" />
    </visual>
    <collision>
      <origin xyz="0.294435 -14.75145 6.922911" rpy="0 0 0" />
      <geometry>
        <box size="25.454088 39.777729 30.544603" />
      </geometry>
    </collision>
    <inertial>
      <mass value="1" />
      <inertia ixx="209.603377" ixy="0" ixz="0" iyy="131.740283" iyz="0" izz="185.848194" />
    </inertial>
  </link>
  <link name="f2l0">
    <visual>
      <geometry>
        <mesh filename="package://glove_description/meshes/f2l0_visual.stl" />
      </geometry>
      <material name="Material_003" />
    </visual>
    <collision>
      <origin xyz="-4.37344 -17.365738 0.199276" rpy="0 0 0" />
      <geometry>
        <box size="38.596191 42.810646 24.533583" />
      </geometry>
    </collision>
    <inertial>
      <mass value="1" />
      <inertia ixx="202.887341" ixy="0" ixz="0" iyy="174.296889" iyz="0" izz="276.868117" />
    </inertial>
  </link>
  <link name="f2xc330">
    <visual>
      <geometry>
        <mesh filename="package://glove_description/meshes/xc330_visual.stl" />
      </geometry>
      <material name="Material_001" />
    </visual>
    <collision>
      <origin xyz="-6.500002 7.499998 0.000002" rpy="0 0 0" />
      <geometry>
        <box size="26.000006 34.000004 20.000002" />
      </geometry>
    </collision>
    <inertial>
      <mass value="1" />
      <inertia ixx="129.666695" ixy="0" ixz="0" iyy="89.666698" iyz="0" izz="152.666713" />
    </inertial>
  </link>
  <link name="f2l1">
    <visual>
      <geometry>
        <mesh filename="package://glove_description/meshes/f2l1_visual.stl" />
      </geometry>
      <material name="Material_003" />
    </visual>
    <collision>
      <origin xyz="1.632236 -48.837238 -0.162706" rpy="0 0 0" />
      <geometry>
        <box size="12.441278 115.97702 18.022671" />
      </geometry>
    </collision>
    <inertial>
      <mass value="1" />
      <inertia ixx="1147.957158" ixy="0" ixz="0" iyy="39.966837" iyz="0" izz="1133.787885" />
    </inertial>
  </link>
  <link name="f2l2">
    <visual>
      <geometry>
        <mesh filename="package://glove_description/meshes/f2l2_visual.stl" />
      </geometry>
      <material name="Material_003" />
    </visual>
    <collision>
      <origin xyz="-1.24935 -29.956436 -0.037106" rpy="0 0 0" />
      <geometry>
        <box size="12.000013 74 14.000005" />
      </geometry>
    </collision>
    <inertial>
      <mass value="1" />
      <inertia ixx="472.666678" ixy="0" ixz="0" iyy="28.333371" iyz="0" izz="468.33336" />
    </inertial>
  </link>
  <link name="f2l3">
    <visual>
      <geometry>
        <mesh filename="package://glove_description/meshes/f2l3_visual.stl" />
      </geometry>
      <material name="Material_003" />
    </visual>
    <collision>
      <origin xyz="0.294447 -14.558609 7.319756" rpy="0 0 0" />
      <geometry>
        <box size="25.454054 39.008659 29.511078" />
      </geometry>
    </collision>
    <inertial>
      <mass value="1" />
      <inertia ixx="199.381602" ixy="0" ixz="0" iyy="126.567715" iyz="0" izz="180.798697" />
    </inertial>
  </link>
  <!-- Joints -->
  <joint name="tl0" type="revolute">
    <origin xyz="57.217976 83.967529 -24.119789" rpy="0 0 0" />
    <parent link="base" />
    <child link="tl0" />
    <axis xyz="1 0 0" />
    <limit effort="10" velocity="1" lower="-3.141593" upper="3.141593" />
    <dynamics damping="0" friction="0" />
  </joint>
  <joint name="Txc330" type="fixed">
    <origin xyz="0.220604 -31.780266 1.792219" rpy="0 0 0" />
    <parent link="tl0" />
    <child link="Txc330" />
  </joint>
  <joint name="tl1" type="revolute">
    <origin xyz="0.653183 0.504234 -9.755316" rpy="0 0 0" />
    <parent link="Txc330" />
    <child link="tl1" />
    <axis xyz="0 0 1" />
    <limit effort="10" velocity="1" lower="-3.141593" upper="3.141593" />
    <dynamics damping="0" friction="0" />
  </joint>
  <joint name="tl2" type="revolute">
    <origin xyz="-0.382935 -99.693802 0.991375" rpy="0 0 0" />
    <parent link="tl1" />
    <child link="tl2" />
    <axis xyz="0 0 1" />
    <limit effort="10" velocity="1" lower="-3.141593" upper="3.141593" />
    <dynamics damping="0" friction="0" />
  </joint>
  <joint name="tl3" type="revolute">
    <origin xyz="-0.062885 -59.897427 0.053812" rpy="0 0 0" />
    <parent link="tl2" />
    <child link="tl3" />
    <axis xyz="0 0 1" />
    <limit effort="10" velocity="1" lower="-3.141593" upper="3.141593" />
    <dynamics damping="0" friction="0" />
  </joint>
  <joint name="bridge" type="fixed">
    <parent link="base" />
    <child link="bridge" />
  </joint>
  <joint name="f1l0" type="revolute">
    <origin xyz="17.717194 -0.927605 20.41119" rpy="0 0 0" />
    <parent link="base" />
    <child link="f1l0" />
    <axis xyz="0 0 1" />
    <limit effort="10" velocity="1" lower="-3.141593" upper="3.141593" />
  </joint>
  <joint name="f1xc330" type="fixed">
    <origin xyz="1.793839 -31.780258 -2.094622" rpy="0 0 0" />
    <parent link="f1l0" />
    <child link="f1xc330" />
    <dynamics damping="0" friction="0" />
  </joint>
  <joint name="f1l1" type="revolute">
    <origin xyz="-9.750091 0.504238 1.160593" rpy="0 0 0" />
    <parent link="f1xc330" />
    <child link="f1l1" />
    <axis xyz="1 0 0" />
    <limit effort="10" velocity="1" lower="-3.141593" upper="3.141593" />
    <dynamics damping="0" friction="0" />
  </joint>
  <joint name="f1l2" type="revolute">
    <origin xyz="0.989426 -99.801514 -0.898172" rpy="0 0 0" />
    <parent link="f1l1" />
    <child link="f1l2" />
    <axis xyz="1 0 0" />
    <limit effort="10" velocity="1" lower="-3.141593" upper="3.141593" />
    <dynamics damping="0" friction="0" />
  </joint>
  <joint name="f1l3" type="revolute">
    <origin xyz="-0.267555 -59.855103 -0.097271" rpy="0 0 0" />
    <parent link="f1l2" />
    <child link="f1l3" />
    <axis xyz="1 0 0" />
    <limit effort="10" velocity="1" lower="-3.141593" upper="3.141593" />
    <dynamics damping="0" friction="0" />
  </joint>
  <joint name="f2l0" type="revolute">
    <origin xyz="-17.623764 -0.927605 19.505016" rpy="0 0 0" />
    <parent link="base" />
    <child link="f2l0" />
    <axis xyz="0 0 1" />
    <limit effort="10" velocity="1" lower="-3.141593" upper="3.141593" />
    <dynamics damping="0" friction="0" />
  </joint>
  <joint name="xc330" type="fixed">
    <origin xyz="-1.793839 -31.780258 -1.680552" rpy="0 0 0" />
    <parent link="f2l0" />
    <child link="f2xc330" />
  </joint>
  <joint name="f2l1" type="revolute">
    <origin xyz="9.750091 0.504238 2.614582" rpy="0 0 0" />
    <parent link="f2xc330" />
    <child link="f2l1" />
    <axis xyz="1 0 0" />
    <limit effort="10" velocity="1" lower="-3.141593" upper="3.141593" />
    <dynamics damping="0" friction="0" />
  </joint>
  <joint name="f2l2" type="revolute">
    <origin xyz="-0.989425 -100.17691 -2.149185" rpy="0 0 0" />
    <parent link="f2l1" />
    <child link="f2l2" />
    <axis xyz="1 0 0" />
    <limit effort="10" velocity="1" lower="-3.141593" upper="3.141593" />
    <dynamics damping="0" friction="0" />
  </joint>
  <joint name="f2l3" type="revolute">
    <origin xyz="0.267555 -59.88974 -0.220499" rpy="0 0 0" />
    <parent link="f2l2" />
    <child link="f2l3" />
    <axis xyz="1 0 0" />
    <limit effort="10" velocity="1" lower="-3.141593" upper="3.141593" />
    <dynamics damping="0" friction="0" />
  </joint>
</robot>